<?xml version="1.0"?>
<robot name="rescue_robot" xmlns:xacro="http://www.ros.org/wiki/xacro">

  <!-- Define properties -->
  <xacro:property name="base_width" value="0.4"/>
  <xacro:property name="base_length" value="0.5"/>
  <xacro:property name="base_height" value="0.15"/>
  <xacro:property name="wheel_radius" value="0.1"/>
  <xacro:property name="wheel_width" value="0.05"/>
  <xacro:property name="wheel_separation" value="0.4"/>
  <xacro:property name="wheel_offset_x" value="0.1"/>

  <!-- Materials -->
  <material name="blue">
    <color rgba="0.2 0.2 1.0 1.0"/>
  </material>
  
  <material name="black">
    <color rgba="0.1 0.1 0.1 1.0"/>
  </material>
  
  <material name="red">
    <color rgba="1.0 0.2 0.2 1.0"/>
  </material>
  
  <material name="gray">
    <color rgba="0.5 0.5 0.5 1.0"/>
  </material>

  <!-- Base Link -->
  <link name="base_link">
    <visual>
      <geometry>
        <box size="${base_length} ${base_width} ${base_height}"/>
      </geometry>
      <material name="blue"/>
    </visual>
    <collision>
      <geometry>
        <box size="${base_length} ${base_width} ${base_height}"/>
      </geometry>
    </collision>
    <inertial>
      <mass value="20.0"/>
      <inertia ixx="0.4" ixy="0.0" ixz="0.0" iyy="0.6" iyz="0.0" izz="0.8"/>
    </inertial>
  </link>

  <!-- Base Footprint (for navigation) -->
  <link name="base_footprint"/>
  
  <joint name="base_footprint_joint" type="fixed">
    <parent link="base_footprint"/>
    <child link="base_link"/>
    <origin xyz="0 0 ${wheel_radius}" rpy="0 0 0"/>
  </joint>

  <!-- Left Wheel -->
  <link name="left_wheel">
    <visual>
      <origin xyz="0 0 0" rpy="1.5708 0 0"/>
      <geometry>
        <cylinder radius="${wheel_radius}" length="${wheel_width}"/>
      </geometry>
      <material name="black"/>
    </visual>
    <collision>
      <origin xyz="0 0 0" rpy="1.5708 0 0"/>
      <geometry>
        <cylinder radius="${wheel_radius}" length="${wheel_width}"/>
      </geometry>
    </collision>
    <inertial>
      <mass value="2.0"/>
      <inertia ixx="0.01" ixy="0.0" ixz="0.0" iyy="0.01" iyz="0.0" izz="0.01"/>
    </inertial>
  </link>

  <joint name="left_wheel_joint" type="continuous">
    <parent link="base_link"/>
    <child link="left_wheel"/>
    <origin xyz="${wheel_offset_x} ${wheel_separation/2 + wheel_width/2} ${-base_height/2}" rpy="0 0 0"/>
    <axis xyz="0 1 0"/>
  </joint>

  <!-- Right Wheel -->
  <link name="right_wheel">
    <visual>
      <origin xyz="0 0 0" rpy="1.5708 0 0"/>
      <geometry>
        <cylinder radius="${wheel_radius}" length="${wheel_width}"/>
      </geometry>
      <material name="black"/>
    </visual>
    <collision>
      <origin xyz="0 0 0" rpy="1.5708 0 0"/>
      <geometry>
        <cylinder radius="${wheel_radius}" length="${wheel_width}"/>
      </geometry>
    </collision>
    <inertial>
      <mass value="2.0"/>
      <inertia ixx="0.01" ixy="0.0" ixz="0.0" iyy="0.01" iyz="0.0" izz="0.01"/>
    </inertial>
  </link>

  <joint name="right_wheel_joint" type="continuous">
    <parent link="base_link"/>
    <child link="right_wheel"/>
    <origin xyz="${wheel_offset_x} ${-wheel_separation/2 - wheel_width/2} ${-base_height/2}" rpy="0 0 0"/>
    <axis xyz="0 1 0"/>
  </joint>

  <!-- Caster Wheel Front -->
  <link name="caster_wheel_front">
    <visual>
      <geometry>
        <sphere radius="0.05"/>
      </geometry>
      <material name="gray"/>
    </visual>
    <collision>
      <geometry>
        <sphere radius="0.05"/>
      </geometry>
    </collision>
    <inertial>
      <mass value="0.5"/>
      <inertia ixx="0.001" ixy="0.0" ixz="0.0" iyy="0.001" iyz="0.0" izz="0.001"/>
    </inertial>
  </link>

  <joint name="caster_wheel_front_joint" type="fixed">
    <parent link="base_link"/>
    <child link="caster_wheel_front"/>
    <origin xyz="0.2 0 ${-base_height/2 - 0.05}" rpy="0 0 0"/>
  </joint>

  <!-- Caster Wheel Back -->
  <link name="caster_wheel_back">
    <visual>
      <geometry>
        <sphere radius="0.05"/>
      </geometry>
      <material name="gray"/>
    </visual>
    <collision>
      <geometry>
        <sphere radius="0.05"/>
      </geometry>
    </collision>
    <inertial>
      <mass value="0.5"/>
      <inertia ixx="0.001" ixy="0.0" ixz="0.0" iyy="0.001" iyz="0.0" izz="0.001"/>
    </inertial>
  </link>

  <joint name="caster_wheel_back_joint" type="fixed">
    <parent link="base_link"/>
    <child link="caster_wheel_back"/>
    <origin xyz="-0.2 0 ${-base_height/2 - 0.05}" rpy="0 0 0"/>
  </joint>

  <!-- Sensor Tower -->
  <link name="sensor_tower">
    <visual>
      <geometry>
        <box size="0.1 0.1 0.3"/>
      </geometry>
      <material name="red"/>
    </visual>
    <collision>
      <geometry>
        <box size="0.1 0.1 0.3"/>
      </geometry>
    </collision>
    <inertial>
      <mass value="1.0"/>
      <inertia ixx="0.01" ixy="0.0" ixz="0.0" iyy="0.01" iyz="0.0" izz="0.01"/>
    </inertial>
  </link>

  <joint name="sensor_tower_joint" type="fixed">
    <parent link="base_link"/>
    <child link="sensor_tower"/>
    <origin xyz="0 0 ${base_height/2 + 0.15}" rpy="0 0 0"/>
  </joint>

  <!-- Laser Scanner -->
  <link name="laser">
    <visual>
      <geometry>
        <cylinder radius="0.05" length="0.04"/>
      </geometry>
      <material name="black"/>
    </visual>
    <collision>
      <geometry>
        <cylinder radius="0.05" length="0.04"/>
      </geometry>
    </collision>
    <inertial>
      <mass value="0.1"/>
      <inertia ixx="0.0001" ixy="0.0" ixz="0.0" iyy="0.0001" iyz="0.0" izz="0.0001"/>
    </inertial>
  </link>

  <joint name="laser_joint" type="fixed">
    <parent link="sensor_tower"/>
    <child link="laser"/>
    <origin xyz="0 0 0.17" rpy="0 0 0"/>
  </joint>

  <!-- RGB Camera -->
  <link name="camera_link">
    <visual>
      <geometry>
        <box size="0.05 0.1 0.05"/>
      </geometry>
      <material name="blue"/>
    </visual>
    <collision>
      <geometry>
        <box size="0.05 0.1 0.05"/>
      </geometry>
    </collision>
    <inertial>
      <mass value="0.1"/>
      <inertia ixx="0.0001" ixy="0.0" ixz="0.0" iyy="0.0001" iyz="0.0" izz="0.0001"/>
    </inertial>
  </link>

  <joint name="camera_joint" type="fixed">
    <parent link="sensor_tower"/>
    <child link="camera_link"/>
    <origin xyz="0.08 0 0.05" rpy="0 0 0"/>
  </joint>

  <!-- Camera Optical Frame -->
  <link name="camera_optical_frame"/>
  
  <joint name="camera_optical_joint" type="fixed">
    <parent link="camera_link"/>
    <child link="camera_optical_frame"/>
    <origin xyz="0 0 0" rpy="-1.5708 0 -1.5708"/>
  </joint>

  <!-- Thermal Camera -->
  <link name="thermal_camera_link">
    <visual>
      <geometry>
        <box size="0.05 0.08 0.05"/>
      </geometry>
      <material name="red"/>
    </visual>
    <collision>
      <geometry>
        <box size="0.05 0.08 0.05"/>
      </geometry>
    </collision>
    <inertial>
      <mass value="0.1"/>
      <inertia ixx="0.0001" ixy="0.0" ixz="0.0" iyy="0.0001" iyz="0.0" izz="0.0001"/>
    </inertial>
  </link>

  <joint name="thermal_camera_joint" type="fixed">
    <parent link="sensor_tower"/>
    <child link="thermal_camera_link"/>
    <origin xyz="0.08 0.06 0.05" rpy="0 0 0"/>
  </joint>

  <!-- IMU -->
  <link name="imu_link">
    <visual>
      <geometry>
        <box size="0.03 0.03 0.01"/>
      </geometry>
      <material name="gray"/>
    </visual>
    <inertial>
      <mass value="0.01"/>
      <inertia ixx="0.00001" ixy="0.0" ixz="0.0" iyy="0.00001" iyz="0.0" izz="0.00001"/>
    </inertial>
  </link>

  <joint name="imu_joint" type="fixed">
    <parent link="base_link"/>
    <child link="imu_link"/>
    <origin xyz="0 0 ${base_height/2}" rpy="0 0 0"/>
  </joint>

  <!-- Gazebo Plugins -->
  
  <!-- Differential Drive Controller -->
  <gazebo>
    <plugin name="differential_drive_controller" filename="libgazebo_ros_diff_drive.so">
      <updateRate>50</updateRate>
      <leftJoint>left_wheel_joint</leftJoint>
      <rightJoint>right_wheel_joint</rightJoint>
      <wheelSeparation>${wheel_separation}</wheelSeparation>
      <wheelDiameter>${2*wheel_radius}</wheelDiameter>
      <wheelAcceleration>1.0</wheelAcceleration>
      <wheelTorque>20</wheelTorque>
      <commandTopic>cmd_vel</commandTopic>
      <odometryTopic>odom</odometryTopic>
      <odometryFrame>odom</odometryFrame>
      <robotBaseFrame>base_footprint</robotBaseFrame>
      <publishWheelTF>false</publishWheelTF>
      <publishWheelJointState>true</publishWheelJointState>
      <publishOdomTF>true</publishOdomTF>
      <odometrySource>world</odometrySource>
      <publishTf>1</publishTf>
    </plugin>
  </gazebo>

  <!-- Laser Scanner Plugin -->
  <gazebo reference="laser">
    <sensor type="ray" name="laser_sensor">
      <pose>0 0 0 0 0 0</pose>
      <visualize>true</visualize>
      <update_rate>10</update_rate>
      <ray>
        <scan>
          <horizontal>
            <samples>360</samples>
            <resolution>1</resolution>
            <min_angle>-3.14159</min_angle>
            <max_angle>3.14159</max_angle>
          </horizontal>
        </scan>
        <range>
          <min>0.2</min>
          <max>30.0</max>
          <resolution>0.01</resolution>
        </range>
        <noise>
          <type>gaussian</type>
          <mean>0.0</mean>
          <stddev>0.01</stddev>
        </noise>
      </ray>
      <plugin name="gazebo_ros_laser" filename="libgazebo_ros_laser.so">
        <topicName>scan</topicName>
        <frameName>laser</frameName>
      </plugin>
    </sensor>
  </gazebo>

  <!-- RGB Camera Plugin -->
  <gazebo reference="camera_link">
    <sensor type="camera" name="camera">
      <update_rate>30.0</update_rate>
      <camera name="front_camera">
        <horizontal_fov>1.3962634</horizontal_fov>
        <image>
          <width>640</width>
          <height>480</height>
          <format>R8G8B8</format>
        </image>
        <clip>
          <near>0.02</near>
          <far>300</far>
        </clip>
        <noise>
          <type>gaussian</type>
          <mean>0.0</mean>
          <stddev>0.007</stddev>
        </noise>
      </camera>
      <plugin name="camera_controller" filename="libgazebo_ros_camera.so">
        <alwaysOn>true</alwaysOn>
        <updateRate>30.0</updateRate>
        <cameraName>camera/rgb</cameraName>
        <imageTopicName>image_raw</imageTopicName>
        <cameraInfoTopicName>camera_info</cameraInfoTopicName>
        <frameName>camera_optical_frame</frameName>
        <hackBaseline>0.07</hackBaseline>
        <distortionK1>0.0</distortionK1>
        <distortionK2>0.0</distortionK2>
        <distortionK3>0.0</distortionK3>
        <distortionT1>0.0</distortionT1>
        <distortionT2>0.0</distortionT2>
      </plugin>
    </sensor>
  </gazebo>

  <!-- Thermal Camera Plugin (simulated as grayscale camera) -->
  <gazebo reference="thermal_camera_link">
    <sensor type="camera" name="thermal_camera">
      <update_rate>10.0</update_rate>
      <camera name="thermal">
        <horizontal_fov>1.3962634</horizontal_fov>
        <image>
          <width>320</width>
          <height>240</height>
          <format>L8</format>
        </image>
        <clip>
          <near>0.02</near>
          <far>100</far>
        </clip>
      </camera>
      <plugin name="thermal_camera_controller" filename="libgazebo_ros_camera.so">
        <alwaysOn>true</alwaysOn>
        <updateRate>10.0</updateRate>
        <cameraName>thermal</cameraName>
        <imageTopicName>image_raw</imageTopicName>
        <cameraInfoTopicName>camera_info</cameraInfoTopicName>
        <frameName>thermal_camera_link</frameName>
      </plugin>
    </sensor>
  </gazebo>

  <!-- IMU Plugin -->
  <gazebo reference="imu_link">
    <sensor name="imu_sensor" type="imu">
      <always_on>true</always_on>
      <update_rate>50</update_rate>
      <plugin filename="libgazebo_ros_imu_sensor.so" name="imu_plugin">
        <topicName>imu</topicName>
        <bodyName>imu_link</bodyName>
        <updateRateHZ>50.0</updateRateHZ>
        <gaussianNoise>0.0</gaussianNoise>
        <xyzOffset>0 0 0</xyzOffset>
        <rpyOffset>0 0 0</rpyOffset>
        <frameName>imu_link</frameName>
      </plugin>
    </sensor>
  </gazebo>

  <!-- Material colors for Gazebo -->
  <gazebo reference="base_link">
    <material>Gazebo/Blue</material>
  </gazebo>
  
  <gazebo reference="left_wheel">
    <material>Gazebo/DarkGrey</material>
    <mu1>1.0</mu1>
    <mu2>1.0</mu2>
  </gazebo>
  
  <gazebo reference="right_wheel">
    <material>Gazebo/DarkGrey</material>
    <mu1>1.0</mu1>
    <mu2>1.0</mu2>
  </gazebo>
  
  <gazebo reference="sensor_tower">
    <material>Gazebo/Red</material>
  </gazebo>

  <gazebo reference="caster_wheel_front">
    <material>Gazebo/Grey</material>
    <mu1>0.0</mu1>
    <mu2>0.0</mu2>
  </gazebo>

  <gazebo reference="caster_wheel_back">
    <material>Gazebo/Grey</material>
    <mu1>0.0</mu1>
    <mu2>0.0</mu2>
  </gazebo>

</robot>
